python version 3.10.7 for x86_64 architecture loaded.
Traceback (most recent call last):
  File "/lustre/projects/project-krishna/WingDiscEversion_theory/Environment/env_WDTheory/lib/python3.10/site-packages/pandas/core/indexes/base.py", line 3629, in get_loc
    return self._engine.get_loc(casted_key)
  File "pandas/_libs/index.pyx", line 136, in pandas._libs.index.IndexEngine.get_loc
  File "pandas/_libs/index.pyx", line 163, in pandas._libs.index.IndexEngine.get_loc
  File "pandas/_libs/hashtable_class_helper.pxi", line 5198, in pandas._libs.hashtable.PyObjectHashTable.get_item
  File "pandas/_libs/hashtable_class_helper.pxi", line 5206, in pandas._libs.hashtable.PyObjectHashTable.get_item
KeyError: 'disc_name'

The above exception was the direct cause of the following exception:

Traceback (most recent call last):
  File "/lustre/projects/project-krishna/WingDiscEversion_theory/Simulations/different_conditions/WT_simulation/mesh_refine_factor_30/Averaging_simulated_curves.py", line 190, in <module>
    discname = thickness_param_comb_df.query("folder_name == @folder").iloc[0]["disc_name"]
  File "/lustre/projects/project-krishna/WingDiscEversion_theory/Environment/env_WDTheory/lib/python3.10/site-packages/pandas/core/series.py", line 958, in __getitem__
    return self._get_value(key)
  File "/lustre/projects/project-krishna/WingDiscEversion_theory/Environment/env_WDTheory/lib/python3.10/site-packages/pandas/core/series.py", line 1069, in _get_value
    loc = self.index.get_loc(label)
  File "/lustre/projects/project-krishna/WingDiscEversion_theory/Environment/env_WDTheory/lib/python3.10/site-packages/pandas/core/indexes/base.py", line 3631, in get_loc
    raise KeyError(key) from err
KeyError: 'disc_name'
